2020-06-29_20:42:56 — file_cache is unavailable when using oauth2client >= 4.0.0 or google-auth
Traceback (most recent call last):
  File "/Users/josephhaaga/anaconda3/lib/python3.7/site-packages/googleapiclient/discovery_cache/__init__.py", line 36, in autodetect
    from google.appengine.api import memcache
ModuleNotFoundError: No module named 'google.appengine'

During handling of the above exception, another exception occurred:

Traceback (most recent call last):
  File "/Users/josephhaaga/anaconda3/lib/python3.7/site-packages/googleapiclient/discovery_cache/file_cache.py", line 33, in <module>
    from oauth2client.contrib.locked_file import LockedFile
ModuleNotFoundError: No module named 'oauth2client'

During handling of the above exception, another exception occurred:

Traceback (most recent call last):
  File "/Users/josephhaaga/anaconda3/lib/python3.7/site-packages/googleapiclient/discovery_cache/file_cache.py", line 37, in <module>
    from oauth2client.locked_file import LockedFile
ModuleNotFoundError: No module named 'oauth2client'

During handling of the above exception, another exception occurred:

Traceback (most recent call last):
  File "/Users/josephhaaga/anaconda3/lib/python3.7/site-packages/googleapiclient/discovery_cache/__init__.py", line 42, in autodetect
    from . import file_cache
  File "/Users/josephhaaga/anaconda3/lib/python3.7/site-packages/googleapiclient/discovery_cache/file_cache.py", line 41, in <module>
    "file_cache is unavailable when using oauth2client >= 4.0.0 or google-auth"
ImportError: file_cache is unavailable when using oauth2client >= 4.0.0 or google-auth
2020-06-29_20:42:56 — URL being requested: GET https://www.googleapis.com/discovery/v1/apis/sheets/v4/rest
2020-06-29_20:42:57 — URL being requested: GET https://sheets.googleapis.com/v4/spreadsheets/1fR7O9sgzjfrYCJN2ITZzFYjHiSQUUf_DkuxsfbutZms/values/Sheet1%21A3%3AB?alt=json
2020-06-29_20:42:57 — NumExpr defaulting to 8 threads.
2020-06-29_20:42:57 — Predicting attempt #3 on a Monday will take: 43.0 seconds
